<?xml version="1.0"?>

<robot xmlns:xacro="http://www.ros.org/wiki/xacro">


	<!-- Things that are needed only for Gazebo (not the physical robot). These include sensor and controller plugin specifications -->
	<xacro:include filename="$(find hyq2max_description)/urdfs/leg/leg.transmission.xacro"/>
	<xacro:include filename="$(find hyq2max_description)/urdfs/leg/leg.gazebo.xacro"/>


	<!-- ================================== Leg ================================== -->
	<!-- The xacro macro xacro:hyq2max_leg contains: hip assembly, upper and lower leg -->
	<xacro:macro name="hyq2max_leg" params="name parent *origin reflect_left reflect_front">
		<!-- Joints -->
		<!-- HAA joint -->
		<joint name="${name}_haa_joint" type="revolute">
			<insert_block name="origin"/>
			<parent link="${parent}"/>
			<child  link="${name}_hipassembly"/>
			<axis xyz="0 0 1"/>
			<dynamics damping="0.1" friction="0" />
			<limit effort="120.0" velocity="12.0" lower="${-2*PI/9}" upper="${2*PI/9}"/>
			<safety_controller k_position="100" k_velocity="100"
							   soft_lower_limit="${-2*PI/9}" soft_upper_limit="${2*PI/9}" />
		</joint>
		<!-- HFE joint -->
		<joint name="${name}_hfe_joint" type="revolute">
			<origin xyz="0 ${-hipassembly_length} 0"
					rpy="${reflect_left*PI/2} 0 0"/>
			<parent link="${name}_hipassembly"/>
			<child  link="${name}_upperleg"/>
			<axis xyz="0 0 1"/>
			<dynamics damping="0.1" friction="0" />
			<limit effort="245.0" velocity="12.0" lower="${-3*PI/4}" upper="${3*PI/4}"/>
			<safety_controller k_position="100" k_velocity="100"
							   soft_lower_limit="${-3*PI/4}" soft_upper_limit="${3*PI/4}" />
		</joint>
		<!-- KFE joint -->
		<joint name="${name}_kfe_joint" type="revolute">
			<origin xyz="${upperleg_length} 0 0" rpy="0 0 ${reflect_front*knee_offset_angle*PI/180}"/>
			<parent link="${name}_upperleg"/>
			<child  link="${name}_lowerleg"/>
			<axis xyz="0 0 1"/>
			<dynamics damping="0.1" friction="0" />
			<limit effort="250.0" velocity="12.0"
				   lower="${(1-reflect_front)*2*PI/360-(1+reflect_front)*167*PI/360}"
				   upper="${-(1+reflect_front)*2*PI/360+(1-reflect_front)*167*PI/360}"/>
			<safety_controller k_position="100" k_velocity="100"
							   soft_lower_limit="${-(1+reflect_front)*167*PI/360}"
							   soft_upper_limit="${(1-reflect_front)*167*PI/360}" />
		</joint>
		<!-- Foot joint -->
		<joint name="${name}_foot_joint" type="fixed">
			<origin xyz="${lowerleg_length} 0 0" rpy="${PI/2} 0 ${-PI/2}"/>
			<parent link="${name}_lowerleg"/>
			<child  link="${name}_foot"/>
		</joint>


		<!-- Links -->
		<!-- Hip assembly link -->
		<link name="${name}_hipassembly">
			<inertial>
				<origin xyz="${xcom_hipassembly} ${ycom_hipassembly} ${zcom_hipassembly}"/>
				<mass value="${m_hipassembly}"/>
				<inertia ixx="${ixx_hipassembly}" iyy="${iyy_hipassembly}" izz="${izz_hipassembly}"
						 ixy="${ixy_hipassembly}" ixz="${ixz_hipassembly}" iyz="${iyz_hipassembly}"/>
			</inertial>
			<visual>
				<origin xyz="0 -0.046 0" rpy="0 ${-PI/2} ${-PI/2}"/><!-- TODO: -0.044 ask Jake -->
				<geometry>
					<mesh filename="package://hyq2max_description/meshes/leg/hipassembly.dae" scale="1 1 1"/>
				</geometry>
			</visual>
			<collision>
				<origin xyz="0 -0.046 0" rpy="0 ${-PI/2} ${-PI/2}"/><!-- TODO: -0.044 ask Jake -->
				<geometry>
					<mesh filename="package://hyq2max_description/meshes/leg/hipassembly.dae" scale="1 1 1"/>
				</geometry>
			</collision>
		</link>
		<!-- Upper leg link -->
		<link name="${name}_upperleg">
			<inertial>
				<origin xyz="${xcom_upperleg} ${reflect_front*ycom_upperleg} ${reflect_left*zcom_upperleg}"/>
				<mass value="${m_upperleg}"/>
				<inertia ixx="${ixx_upperleg}" iyy="${iyy_upperleg}" izz="${izz_upperleg}"
						 ixy="${reflect_front*ixy_upperleg}" ixz="${reflect_left*ixz_upperleg}" iyz="${reflect_left*reflect_front*iyz_upperleg}"/>
			</inertial>
			<visual> 
				<origin xyz="0 0 ${-0.03*reflect_left}" rpy="${(1-reflect_left)*PI/2} 0 0"/> <!-- TODO Ask displacement Jake -->
				<geometry>
					<mesh filename="package://hyq2max_description/meshes/leg/upperleg.dae" scale="1 1 1"/>
				</geometry>
			</visual>
			<collision>
				<origin xyz="0 0 ${-0.03*reflect_left}" rpy="${(1-reflect_left)*PI/2} 0 0"/> <!-- TODO Ask displacement Jake -->
				<geometry>
					<mesh filename="package://hyq2max_description/meshes/leg/upperleg.dae" scale="1 1 1"/>
				</geometry>
			</collision>
		</link>
		<!-- Lower leg link -->
		<link name="${name}_lowerleg">
			<inertial>
				<origin xyz="${xcom_lowerleg} ${reflect_front*ycom_lowerleg} ${reflect_front*zcom_lowerleg}"/>
				<mass value="${m_lowerleg}"/>
				<inertia ixx="${ixx_lowerleg}" iyy="${iyy_lowerleg}" izz="${izz_lowerleg}"
						 ixy="${reflect_front*ixy_lowerleg}" ixz="${reflect_front*ixz_lowerleg}" iyz="${iyz_lowerleg}"/>
			</inertial>
			<visual>
				<origin xyz="0 0 0" rpy="${(1-reflect_front)*PI/2} 0 ${PI-reflect_front*knee_offset_angle*PI/180}"/>
				<geometry>
					<mesh filename="package://hyq2max_description/meshes/leg/lowerleg.dae" scale="1 1 1"/>
				</geometry>
				<material name="white"/>
			</visual>
			<collision>
				<origin xyz="0 0 0" rpy="${(1-reflect_front)*PI/2} 0 ${PI-reflect_front*knee_offset_angle*PI/180}"/>
				<geometry>
					<mesh filename="package://hyq2max_description/meshes/leg/lowerleg.dae" scale="1 1 1"/>
				</geometry>
			</collision>
		</link>
		<!-- Foot link -->
		<link name="${name}_foot">
			<inertial>
				<origin xyz="0 0 0"/>
				<mass value="0.0"/>
				<inertia ixx="0.0" iyy="0.0" izz="0.0" ixy="0.0" ixz="0.0" iyz="0.0"/>
			</inertial>
			<!--<visual>
				<origin xyz="0.0 0.0 0.0" rpy="0.0 0.0 0.0"/>
				<geometry>
					<sphere radius="0.021"/>
				</geometry>
			</visual>-->
			<collision>
				<origin xyz="0 0 0" rpy="0 0 0"/>
				<geometry>
					<sphere radius="0.02175"/>
				</geometry>
			</collision>
		</link>
		
		<!-- Extensions -->
		<xacro:leg_transmission name="${name}"/>
		<xacro:leg_gazebo name="${name}"/>
	</xacro:macro>

</robot>
